Workbook

Sheet ۰۰_راهنما
A1: 🧠 برنامه جامع SEO دکتر مسقط — مرجع کلیدواژه‌ها
A3: 📊 | B3: این فایل شامل بیش از ۶۰۰ کلمه کلیدی دقیق برای SEO دکتر مسقط است.
B4: همه‌ٔ بازار سلامت عُمان را پوشش می‌دهد: درمانی، تخصصی، دارویی، آزمایشگاهی، تجهیزات، تندرستی و فرهنگی.
A6: 🗂️ | B6: ساختار فایل — ۱۸ شیت سازماندهی‌شده:
B7: ۰۰_راهنما — این شیت
B8: ۰۱_Master — همه ۶۰۰+ کلیدواژه در یک جدول
B9: ۰۲_Categories — فهرست همه ۹۰+ تخصص و دسته با ترجمه
B10: ۰۳_Locations — همه مناطق فعال در عُمان
B11: ۰۴_Tier1_Money — کلیدواژه‌های پولساز (Best Specialty Muscat)
B12: ۰۵_Tier2_Programmatic — ترکیب تخصص × منطقه (۲۴۰ کلمه)
B13: ۰۶_Tier3_Costs — کلیدواژه‌های هزینه و قیمت
B14: ۰۷_Tier4_Symptoms — علائم و درمان‌ها
B15: ۰۸_Tier5_Drugs — داروها، ویتامین‌ها، اسکین‌کر
B16: ۰۹_Tier6_LabImaging — آزمایش‌ها و تصویربرداری
B17: ۱۰_Tier7_Wellness — تندرستی، باشگاه، تغذیه، یوگا
B18: ۱۱_Tier8_Devices — تجهیزات و دستگاه‌های پزشکی
... B24: ۱۷_URL_Strategy — استراتژی ساختار URL
A26: 🎨 | B26: رنگ‌بندی Tier‌ها:
B27: 🟨 Tier 1 — طلایی: کلمات پولساز اصلی
B28: 🟦 Tier 2 — فیروزه‌ای: Programmatic (تخصص × منطقه)
B29: 🌸 Tier 3 — رز: هزینه و قیمت
B30: 💜 Tier 4 — بنفش: علائم و درمان
B31: 🔵 Tier 5 — آبی: داروها و ویتامین‌ها
B32: 🟢 Tier 6 — سبز: آزمایش و تصویربرداری
B33: 🟧 Tier 7 — نارنجی: تندرستی و تغذیه
B34: ⚪ Tier 8 — خاکستری: تجهیزات پزشکی
B35: 🟣 Tier 9 — فوشیا: بیمه
B36: 🟡 Tier 10 — کهربایی: فرهنگی و فصلی
A38: ⚡ | B38: ستون Priority Score چه می‌گوید؟
B39: فرمول: (Intent × log10(Volume)) / Competition
B40: هرچه عدد بالاتر = اولویت بالاتر (سبز پررنگ)
B41: Intent: Transactional=5، Commercial=4، Comparison=3، Informational=2
B42: Competition: High=5، Medium=3، Low=1
B43: اگر Actual Volume را پر کنید، فرمول از آن استفاده می‌کند.
A45: ✍️ | B45: ستون‌هایی که شما باید پر کنید:
B46: Actual Volume — حجم دقیق از Google Keyword Planner
B47: Actual Competition — رقابت دقیق از Ahrefs/Ubersuggest
B48: Current Rank — رتبه فعلی در گوگل (با VPN عُمان چک کنید)
B49: Status — وضعیت پیشرفت از منوی کشویی
B50: Notes — هر نکته‌ای که می‌خواهید برای این کلمه یادتان باشد
...

Sheet ۰۱_Master
A1: # | B1: Tier | C1: Lang | D1: Keyword | E1: Intent | F1: Est. Volume | G1: Est. Comp. | H1: Pattern | I1: Cluster | J1: Target URL | K1: Priority | L1: Actual Vol. | M1: Actual Diff. | N1: Current Rank | O1: Status | P1: Notes
A2: 1 | B2: 1 | C2: EN | D2: best Dentist Muscat | E2: Commercial | F2: 1000-2500 | G2: High | H2: Money-City | I2: Dental | J2: /en/dentist | K2: =ROUND((IF(E2="Transactional",5,IF(E2="Commercial",4,IF(E2="Comparison",3,IF(E2="Informational",2,3))))*LOG10(IF(ISNUMBER(L2),L2,IFERROR(VALUE(LEFT(F2,FIND("-",F2)-1)),100))+1))/IF(IF(ISBLANK(M2),G2,M2)="High",5,IF(IF(ISBLANK(M2),G2,M2)="Medium",3,1)),2) -> 2.4 | O2: Not Started | P2: بهترین Dentist در مسقط — کلمه پربازدید
A3: 2 | B3: 1 | C3: AR | D3: أفضل طبيب أسنان مسقط | E3: Commercial | F3: 800-2000 | G3: High | H3: Money-City | I3: Dental | J3: /ar/dentist | K3: =ROUND((IF(E3="Transactional",5,IF(E3="Commercial",4,IF(E3="Comparison",3,IF(E3="Informational",2,3))))*LOG10(IF(ISNUMBER(L3),L3,IFERROR(VALUE(LEFT(F3,FIND("-",F3)-1)),100))+1))/IF(IF(ISBLANK(M3),G3,M3)="High",5,IF(IF(ISBLANK(M3),G3,M3)="Medium",3,1)),2) -> 2.32 | O3: Not Started | P3: رقابت کم‌تر در عربی، اولویت بالاتر
A4: 3 | B4: 1 | C4: EN | D4: best Dental Clinic Muscat | E4: Commercial | F4: 1000-2500 | G4: High | H4: Money-City | I4: Dental | J4: /en/dental-clinic | K4: =ROUND((IF(E4="Transactional",5,IF(E4="Commercial",4,IF(E4="Comparison",3,IF(E4="Informational",2,3))))*LOG10(IF(ISNUMBER(L4),L4,IFERROR(VALUE(LEFT(F4,FIND("-",F4)-1)),100))+1))/IF(IF(ISBLANK(M4),G4,M4)="High",5,IF(IF(ISBLANK(M4),G4,M4)="Medium",3,1)),2) -> 2.4 | O4: Not Started | P4: بهترین Dental Clinic در مسقط — کلمه پربازدید
A5: 4 | B5: 1 | C5: AR | D5: أفضل عيادة أسنان مسقط | E5: Commercial | F5: 800-2000 | G5: High | H5: Money-City | I5: Dental | J5: /ar/dental-clinic | K5: =ROUND((IF(E5="Transactional",5,IF(E5="Commercial",4,IF(E5="Comparison",3,IF(E5="Informational",2,3))))*LOG10(IF(ISNUMBER(L5),L5,IFERROR(VALUE(LEFT(F5,FIND("-",F5)-1)),100))+1))/IF(IF(ISBLANK(M5),G5,M5)="High",5,IF(IF(ISBLANK(M5),G5,M5)="Medium",3,1)),2) -> 2.32 | O5: Not Started | P5: رقابت کم‌تر در عربی، اولویت بالاتر
A6: 5 | B6: 1 | C6: EN | D6: best Orthodontist Muscat | E6: Commercial | F6: 400-1000 | G6: Medium | H6: Money-City | I6: Dental | J6: /en/orthodontist | K6: =ROUND((IF(E6="Transactional",5,IF(E6="Commercial",4,IF(E6="Comparison",3,IF(E6="Informational",2,3))))*LOG10(IF(ISNUMBER(L6),L6,IFERROR(VALUE(LEFT(F6,FIND("-",F6)-1)),100))+1))/IF(IF(ISBLANK(M6),G6,M6)="High",5,IF(IF(ISBLANK(M6),G6,M6)="Medium",3,1)),2) -> 3.47 | O6: Not Started | P6: بهترین Orthodontist در مسقط — کلمه پربازدید
A7: 6 | B7: 1 | C7: AR | D7: أفضل تقويم الأسنان مسقط | E7: Commercial | F7: 350-800 | G7: Medium | H7: Money-City | I7: Dental | J7: /ar/orthodontist | K7: =ROUND((IF(E7="Transactional",5,IF(E7="Commercial",4,IF(E7="Comparison",3,IF(E7="Informational",2,3))))*LOG10(IF(ISNUMBER(L7),L7,IFERROR(VALUE(LEFT(F7,FIND("-",F7)-1)),100))+1))/IF(IF(ISBLANK(M7),G7,M7)="High",5,IF(IF(ISBLANK(M7),G7,M7)="Medium",3,1)),2) -> 3.39 | O7: Not Started | P7: رقابت کم‌تر در عربی، اولویت بالاتر
A8: 7 | B8: 1 | C8: EN | D8: best Cosmetic Dentist Muscat | E8: Commercial | F8: 400-1000 | G8: Medium | H8: Money-City | I8: Dental | J8: /en/cosmetic-dentist | K8: =ROUND((IF(E8="Transactional",5,IF(E8="Commercial",4,IF(E8="Comparison",3,IF(E8="Informational",2,3))))*LOG10(IF(ISNUMBER(L8),L8,IFERROR(VALUE(LEFT(F8,FIND("-",F8)-1)),100))+1))/IF(IF(ISBLANK(M8),G8,M8)="High",5,IF(IF(ISBLANK(M8),G8,M8)="Medium",3,1)),2) -> 3.47 | O8: Not Started | P8: بهترین Cosmetic Dentist در مسقط — کلمه پربازدید
A9: 8 | B9: 1 | C9: AR | D9: أفضل تجميل الأسنان مسقط | E9: Commercial | F9: 350-800 | G9: Medium | H9: Money-City | I9: Dental | J9: /ar/cosmetic-dentist | K9: =ROUND((IF(E9="Transactional",5,IF(E9="Commercial",4,IF(E9="Comparison",3,IF(E9="Informational",2,3))))*LOG10(IF(ISNUMBER(L9),L9,IFERROR(VALUE(LEFT(F9,FIND("-",F9)-1)),100))+1))/IF(IF(ISBLANK(M9),G9,M9)="High",5,IF(IF(ISBLANK(M9),G9,M9)="Medium",3,1)),2) -> 3.39 | O9: Not Started | P9: رقابت کم‌تر در عربی، اولویت بالاتر
A10: 9 | B10: 1 | C10: EN | D10: best Pediatric Dentist Muscat | E10: Commercial | F10: 400-1000 | G10: Medium | H10: Money-City | I10: Dental | J10: /en/pediatric-dentist | K10: =ROUND((IF(E10="Transactional",5,IF(E10="Commercial",4,IF(E10="Comparison",3,IF(E10="Informational",2,3))))*LOG10(IF(ISNUMBER(L10),L10,IFERROR(VALUE(LEFT(F10,FIND("-",F10)-1)),100))+1))/IF(IF(ISBLANK(M10),G10,M10)="High",5,IF(IF(ISBLANK(M10),G10,M10)="Medium",3,1)),2) -> 3.47 | O10: Not Started | P10: بهترین Pediatric Dentist در مسقط — کلمه پربازدید
A11: 10 | B11: 1 | C11: AR | D11: أفضل طبيب أسنان أطفال مسقط | E11: Commercial | F11: 350-800 | G11: Medium | H11: Money-City | I11: Dental | J11: /ar/pediatric-dentist | K11: =ROUND((IF(E11="Transactional",5,IF(E11="Commercial",4,IF(E11="Comparison",3,IF(E11="Informational",2,3))))*LOG10(IF(ISNUMBER(L11),L11,IFERROR(VALUE(LEFT(F11,FIND("-",F11)-1)),100))+1))/IF(IF(ISBLANK(M11),G11,M11)="High",5,IF(IF(ISBLANK(M11),G11,M11)="Medium",3,1)),2) -> 3.39 | O11: Not Started | P11: رقابت کم‌تر در عربی، اولویت بالاتر
A12: 11 | B12: 1 | C12: EN | D12: best Dental Implant Muscat | E12: Commercial | F12: 1000-2500 | G12: High | H12: Money-City | I12: Dental | J12: /en/dental-implant | K12: =ROUND((IF(E12="Transactional",5,IF(E12="Commercial",4,IF(E12="Comparison",3,IF(E12="Informational",2,3))))*LOG10(IF(ISNUMBER(L12),L12,IFERROR(VALUE(LEFT(F12,FIND("-",F12)-1)),100))+1))/IF(IF(ISBLANK(M12),G12,M12)="High",5,IF(IF(ISBLANK(M12),G12,M12)="Medium",3,1)),2) -> 2.4 | O12: Not Started | P12: بهترین Dental Implant در مسقط — کلمه پربازدید
A13: 12 | B13: 1 | C13: AR | D13: أفضل زرع الأسنان مسقط | E13: Commercial | F13: 800-2000 | G13: High | H13: Money-City | I13: Dental | J13: /ar/dental-implant | K13: =ROUND((IF(E13="Transactional",5,IF(E13="Commercial",4,IF(E13="Comparison",3,IF(E13="Informational",2,3))))*LOG10(IF(ISNUMBER(L13),L13,IFERROR(VALUE(LEFT(F13,FIND("-",F13)-1)),100))+1))/IF(IF(ISBLANK(M13),G13,M13)="High",5,IF(IF(ISBLANK(M13),G13,M13)="Medium",3,1)),2) -> 2.32 | O13: Not Started | P13: رقابت کم‌تر در عربی، اولویت بالاتر
... A142: 141 | B142: 2 | C142: EN | D142: Dentist Al Mouj | E142: Commercial | F142: 40-100 | G142: Low | H142: Loc+Cat | I142: Dental | J142: /en/dentist/al-mouj | K142: =ROUND((IF(E142="Transactional",5,IF(E142="Commercial",4,IF(E142="Comparison",3,IF(E142="Informational",2,3))))*LOG10(IF(ISNUMBER(L142),L142,IFERROR(VALUE(LEFT(F142,FIND("-",F142)-1)),100))+1))/IF(IF(ISBLANK(M142),G142,M142)="High",5,IF(IF(ISBLANK(M142),G142,M142)="Medium",3,1)),2) -> 6.45 | O142: Not Started | P142: long-tail با رقابت پایین
A143: 142 | B143: 2 | C143: AR | D143: طبيب أسنان الموج | E143: Commercial | F143: 40-100 | G143: Low | H143: Loc+Cat | I143: Dental | J143: /ar/dentist/al-mouj | K143: =ROUND((IF(E143="Transactional",5,IF(E143="Commercial",4,IF(E143="Comparison",3,IF(E143="Informational",2,3))))*LOG10(IF(ISNUMBER(L143),L143,IFERROR(VALUE(LEFT(F143,FIND("-",F143)-1)),100))+1))/IF(IF(ISBLANK(M143),G143,M143)="High",5,IF(IF(ISBLANK(M143),G143,M143)="Medium",3,1)),2) -> 6.45 | O143: Not Started
A144: 143 | B144: 2 | C144: EN | D144: Dentist Al Qurum | E144: Commercial | F144: 40-100 | G144: Low | H144: Loc+Cat | I144: Dental | J144: /en/dentist/al-qurum | K144: =ROUND((IF(E144="Transactional",5,IF(E144="Commercial",4,IF(E144="Comparison",3,IF(E144="Informational",2,3))))*LOG10(IF(ISNUMBER(L144),L144,IFERROR(VALUE(LEFT(F144,FIND("-",F144)-1)),100))+1))/IF(IF(ISBLANK(M144),G144,M144)="High",5,IF(IF(ISBLANK(M144),G144,M144)="Medium",3,1)),2) -> 6.45 | O144: Not Started | P144: long-tail با رقابت پایین
A145: 144 | B145: 2 | C145: AR | D145: طبيب أسنان القرم | E145: Commercial | F145: 40-100 | G145: Low | H145: Loc+Cat | I145: Dental | J145: /ar/dentist/al-qurum | K145: =ROUND((IF(E145="Transactional",5,IF(E145="Commercial",4,IF(E145="Comparison",3,IF(E145="Informational",2,3))))*LOG10(IF(ISNUMBER(L145),L145,IFERROR(VALUE(LEFT(F145,FIND("-",F145)-1)),100))+1))/IF(IF(ISBLANK(M145),G145,M145)="High",5,IF(IF(ISBLANK(M145),G145,M145)="Medium",3,1)),2) -> 6.45 | O145: Not Started
A146: 145 | B146: 2 | C146: EN | D146: Dentist Al Khuwair | E146: Commercial | F146: 40-100 | G146: Low | H146: Loc+Cat | I146: Dental | J146: /en/dentist/al-khuwair | K146: =ROUND((IF(E146="Transactional",5,IF(E146="Commercial",4,IF(E146="Comparison",3,IF(E146="Informational",2,3))))*LOG10(IF(ISNUMBER(L146),L146,IFERROR(VALUE(LEFT(F146,FIND("-",F146)-1)),100))+1))/IF(IF(ISBLANK(M146),G146,M146)="High",5,IF(IF(ISBLANK(M146),G146,M146)="Medium",3,1)),2) -> 6.45 | O146: Not Started | P146: long-tail با رقابت پایین
A147: 146 | B147: 2 | C147: AR | D147: طبيب أسنان الخوير | E147: Commercial | F147: 40-100 | G147: Low | H147: Loc+Cat | I147: Dental | J147: /ar/dentist/al-khuwair | K147: =ROUND((IF(E147="Transactional",5,IF(E147="Commercial",4,IF(E147="Comparison",3,IF(E147="Informational",2,3))))*LOG10(IF(ISNUMBER(L147),L147,IFERROR(VALUE(LEFT(F147,FIND("-",F147)-1)),100))+1))/IF(IF(ISBLANK(M147),G147,M147)="High",5,IF(IF(ISBLANK(M147),G147,M147)="Medium",3,1)),2) -> 6.45 | O147: Not Started
A148: 147 | B148: 2 | C148: EN | D148: Dentist Madinat Sultan Qaboos | E148: Commercial | F148: 40-100 | G148: Low | H148: Loc+Cat | I148: Dental | J148: /en/dentist/madinat-sultan-qaboos | K148: =ROUND((IF(E148="Transactional",5,IF(E148="Commercial",4,IF(E148="Comparison",3,IF(E148="Informational",2,3))))*LOG10(IF(ISNUMBER(L148),L148,IFERROR(VALUE(LEFT(F148,FIND("-",F148)-1)),100))+1))/IF(IF(ISBLANK(M148),G148,M148)="High",5,IF(IF(ISBLANK(M148),G148,M148)="Medium",3,1)),2) -> 6.45 | O148: Not Started | P148: long-tail با رقابت پایین
A149: 148 | B149: 2 | C149: AR | D149: طبيب أسنان مدينة السلطان قابوس | E149: Commercial | F149: 40-100 | G149: Low | H149: Loc+Cat | I149: Dental | J149: /ar/dentist/madinat-sultan-qaboos | K149: =ROUND((IF(E149="Transactional",5,IF(E149="Commercial",4,IF(E149="Comparison",3,IF(E149="Informational",2,3))))*LOG10(IF(ISNUMBER(L149),L149,IFERROR(VALUE(LEFT(F149,FIND("-",F149)-1)),100))+1))/IF(IF(ISBLANK(M149),G149,M149)="High",5,IF(IF(ISBLANK(M149),G149,M149)="Medium",3,1)),2) -> 6.45 | O149: Not Started
A150: 149 | B150: 2 | C150: EN | D150: Dentist Al Ghubra | E150: Commercial | F150: 40-100 | G150: Low | H150: Loc+Cat | I150: Dental | J150: /en/dentist/al-ghubra | K150: =ROUND((IF(E150="Transactional",5,IF(E150="Commercial",4,IF(E150="Comparison",3,IF(E150="Informational",2,3))))*LOG10(IF(ISNUMBER(L150),L150,IFERROR(VALUE(LEFT(F150,FIND("-",F150)-1)),100))+1))/IF(IF(ISBLANK(M150),G150,M150)="High",5,IF(IF(ISBLANK(M150),G150,M150)="Medium",3,1)),2) -> 6.45 | O150: Not Started | P150: long-tail با رقابت پایین
A151: 150 | B151: 2 | C151: AR | D151: طبيب أسنان الغبرة | E151: Commercial | F151: 40-100 | G151: Low | H151: Loc+Cat | I151: Dental | J151: /ar/dentist/al-ghubra | K151: =ROUND((IF(E151="Transactional",5,IF(E151="Commercial",4,IF(E151="Comparison",3,IF(E151="Informational",2,3))))*LOG10(IF(ISNUMBER(L151),L151,IFERROR(VALUE(LEFT(F151,FIND("-",F151)-1)),100))+1))/IF(IF(ISBLANK(M151),G151,M151)="High",5,IF(IF(ISBLANK(M151),G151,M151)="Medium",3,1)),2) -> 6.45 | O151: Not Started
A152: 151 | B152: 2 | C152: EN | D152: Dentist Ruwi | E152: Commercial | F152: 40-100 | G152: Low | H152: Loc+Cat | I152: Dental | J152: /en/dentist/ruwi | K152: =ROUND((IF(E152="Transactional",5,IF(E152="Commercial",4,IF(E152="Comparison",3,IF(E152="Informational",2,3))))*LOG10(IF(ISNUMBER(L152),L152,IFERROR(VALUE(LEFT(F152,FIND("-",F152)-1)),100))+1))/IF(IF(ISBLANK(M152),G152,M152)="High",5,IF(IF(ISBLANK(M152),G152,M152)="Medium",3,1)),2) -> 6.45 | O152: Not Started | P152: long-tail با رقابت پایین
A153: 152 | B153: 2 | C153: AR | D153: طبيب أسنان روي | E153: Commercial | F153: 40-100 | G153: Low | H153: Loc+Cat | I153: Dental | J153: /ar/dentist/ruwi | K153: =ROUND((IF(E153="Transactional",5,IF(E153="Commercial",4,IF(E153="Comparison",3,IF(E153="Informational",2,3))))*LOG10(IF(ISNUMBER(L153),L153,IFERROR(VALUE(LEFT(F153,FIND("-",F153)-1)),100))+1))/IF(IF(ISBLANK(M153),G153,M153)="High",5,IF(IF(ISBLANK(M153),G153,M153)="Medium",3,1)),2) -> 6.45 | O153: Not Started
A154: 153 | B154: 2 | C154: EN | D154: Dentist Bawshar | E154: Commercial | F154: 40-100 | G154: Low | H154: Loc+Cat | I154: Dental | J154: /en/dentist/bawshar | K154: =ROUND((IF(E154="Transactional",5,IF(E154="Commercial",4,IF(E154="Comparison",3,IF(E154="Informational",2,3))))*LOG10(IF(ISNUMBER(L154),L154,IFERROR(VALUE(LEFT(F154,FIND("-",F154)-1)),100))+1))/IF(IF(ISBLANK(M154),G154,M154)="High",5,IF(IF(ISBLANK(M154),G154,M154)="Medium",3,1)),2) -> 6.45 | O154: Not Started | P154: long-tail با رقابت پایین
A155: 154 | B155: 2 | C155: AR | D155: طبيب أسنان بوشر | E155: Commercial | F155: 40-100 | G155: Low | H155: Loc+Cat | I155: Dental | J155: /ar/dentist/bawshar | K155: =ROUND((IF(E155="Transactional",5,IF(E155="Commercial",4,IF(E155="Comparison",3,IF(E155="Informational",2,3))))*LOG10(IF(ISNUMBER(L155),L155,IFERROR(VALUE(LEFT(F155,FIND("-",F155)-1)),100))+1))/IF(IF(ISBLANK(M155),G155,M155)="High",5,IF(IF(ISBLANK(M155),G155,M155)="Medium",3,1)),2) -> 6.45 | O155: Not Started
A156: 155 | B156: 2 | C156: EN | D156: Dentist Al Khoud | E156: Commercial | F156: 40-100 | G156: Low | H156: Loc+Cat | I156: Dental | J156: /en/dentist/al-khoud | K156: =ROUND((IF(E156="Transactional",5,IF(E156="Commercial",4,IF(E156="Comparison",3,IF(E156="Informational",2,3))))*LOG10(IF(ISNUMBER(L156),L156,IFERROR(VALUE(LEFT(F156,FIND("-",F156)-1)),100))+1))/IF(IF(ISBLANK(M156),G156,M156)="High",5,IF(IF(ISBLANK(M156),G156,M156)="Medium",3,1)),2) -> 6.45 | O156: Not Started | P156: long-tail با رقابت پایین
A157: 156 | B157: 2 | C157: AR | D157: طبيب أسنان الخوض | E157: Commercial | F157: 40-100 | G157: Low | H157: Loc+Cat | I157: Dental | J157: /ar/dentist/al-khoud | K157: =ROUND((IF(E157="Transactional",5,IF(E157="Commercial",4,IF(E157="Comparison",3,IF(E157="Informational",2,3))))*LOG10(IF(ISNUMBER(L157),L157,IFERROR(VALUE(LEFT(F157,FIND("-",F157)-1)),100))+1))/IF(IF(ISBLANK(M157),G157,M157)="High",5,IF(IF(ISBLANK(M157),G157,M157)="Medium",3,1)),2) -> 6.45 | O157: Not Started
A158: 157 | B158: 2 | C158: EN | D158: Dental Clinic Al Mouj | E158: Commercial | F158: 40-100 | G158: Low | H158: Loc+Cat | I158: Dental | J158: /en/dental-clinic/al-mouj | K158: =ROUND((IF(E158="Transactional",5,IF(E158="Commercial",4,IF(E158="Comparison",3,IF(E158="Informational",2,3))))*LOG10(IF(ISNUMBER(L158),L158,IFERROR(VALUE(LEFT(F158,FIND("-",F158)-1)),100))+1))/IF(IF(ISBLANK(M158),G158,M158)="High",5,IF(IF(ISBLANK(M158),G158,M158)="Medium",3,1)),2) -> 6.45 | O158: Not Started | P158: long-tail با رقابت پایین
A159: 158 | B159: 2 | C159: AR | D159: عيادة أسنان الموج | E159: Commercial | F159: 40-100 | G159: Low | H159: Loc+Cat | I159: Dental | J159: /ar/dental-clinic/al-mouj | K159: =ROUND((IF(E159="Transactional",5,IF(E159="Commercial",4,IF(E159="Comparison",3,IF(E159="Informational",2,3))))*LOG10(IF(ISNUMBER(L159),L159,IFERROR(VALUE(LEFT(F159,FIND("-",F159)-1)),100))+1))/IF(IF(ISBLANK(M159),G159,M159)="High",5,IF(IF(ISBLANK(M159),G159,M159)="Medium",3,1)),2) -> 6.45 | O159: Not Started
A160: 159 | B160: 2 | C160: EN | D160: Dental Clinic Al Qurum | E160: Commercial | F160: 40-100 | G160: Low | H160: Loc+Cat | I160: Dental | J160: /en/dental-clinic/al-qurum | K160: =ROUND((IF(E160="Transactional",5,IF(E160="Commercial",4,IF(E160="Comparison",3,IF(E160="Informational",2,3))))*LOG10(IF(ISNUMBER(L160),L160,IFERROR(VALUE(LEFT(F160,FIND("-",F160)-1)),100))+1))/IF(IF(ISBLANK(M160),G160,M160)="High",5,IF(IF(ISBLANK(M160),G160,M160)="Medium",3,1)),2) -> 6.45 | O160: Not Started | P160: long-tail با رقابت پایین
A161: 160 | B161: 2 | C161: AR | D161: عيادة أسنان القرم | E161: Commercial | F161: 40-100 | G161: Low | H161: Loc+Cat | I161: Dental | J161: /ar/dental-clinic/al-qurum | K161: =ROUND((IF(E161="Transactional",5,IF(E161="Commercial",4,IF(E161="Comparison",3,IF(E161="Informational",2,3))))*LOG10(IF(ISNUMBER(L161),L161,IFERROR(VALUE(LEFT(F161,FIND("-",F161)-1)),100))+1))/IF(IF(ISBLANK(M161),G161,M161)="High",5,IF(IF(ISBLANK(M161),G161,M161)="Medium",3,1)),2) -> 6.45 | O161: Not Started
A162: 161 | B162: 2 | C162: EN | D162: Dental Clinic Al Khuwair | E162: Commercial | F162: 40-100 | G162: Low | H162: Loc+Cat | I162: Dental | J162: /en/dental-clinic/al-khuwair | K162: =ROUND((IF(E162="Transactional",5,IF(E162="Commercial",4,IF(E162="Comparison",3,IF(E162="Informational",2,3))))*LOG10(IF(ISNUMBER(L162),L162,IFERROR(VALUE(LEFT(F162,FIND("-",F162)-1)),100))+1))/IF(IF(ISBLANK(M162),G162,M162)="High",5,IF(IF(ISBLANK(M162),G162,M162)="Medium",3,1)),2) -> 6.45 | O162: Not Started | P162: long-tail با رقابت پایین
A163: 162 | B163: 2 | C163: AR | D163: عيادة أسنان الخوير | E163: Commercial | F163: 40-100 | G163: Low | H163: Loc+Cat | I163: Dental | J163: /ar/dental-clinic/al-khuwair | K163: =ROUND((IF(E163="Transactional",5,IF(E163="Commercial",4,IF(E163="Comparison",3,IF(E163="Informational",2,3))))*LOG10(IF(ISNUMBER(L163),L163,IFERROR(VALUE(LEFT(F163,FIND("-",F163)-1)),100))+1))/IF(IF(ISBLANK(M163),G163,M163)="High",5,IF(IF(ISBLANK(M163),G163,M163)="Medium",3,1)),2) -> 6.45 | O163: Not Started
A164: 163 | B164: 2 | C164: EN | D164: Dental Clinic Madinat Sultan Qaboos | E164: Commercial | F164: 40-100 | G164: Low | H164: Loc+Cat | I164: Dental | J164: /en/dental-clinic/madinat-sultan-qaboos | K164: =ROUND((IF(E164="Transactional",5,IF(E164="Commercial",4,IF(E164="Comparison",3,IF(E164="Informational",2,3))))*LOG10(IF(ISNUMBER(L164),L164,IFERROR(VALUE(LEFT(F164,FIND("-",F164)-1)),100))+1))/IF(IF(ISBLANK(M164),G164,M164)="High",5,IF(IF(ISBLANK(M164),G164,M164)="Medium",3,1)),2) -> 6.45 | O164: Not Started | P164: long-tail با رقابت پایین
A165: 164 | B165: 2 | C165: AR | D165: عيادة أسنان مدينة السلطان قابوس | E165: Commercial | F165: 40-100 | G165: Low | H165: Loc+Cat | I165: Dental | J165: /ar/dental-clinic/madinat-sultan-qaboos | K165: =ROUND((IF(E165="Transactional",5,IF(E165="Commercial",4,IF(E165="Comparison",3,IF(E165="Informational",2,3))))*LOG10(IF(ISNUMBER(L165),L165,IFERROR(VALUE(LEFT(F165,FIND("-",F165)-1)),100))+1))/IF(IF(ISBLANK(M165),G165,M165)="High",5,IF(IF(ISBLANK(M165),G165,M165)="Medium",3,1)),2) -> 6.45 | O165: Not Started
A166: 165 | B166: 2 | C166: EN | D166: Dental Clinic Al Ghubra | E166: Commercial | F166: 40-100 | G166: Low | H166: Loc+Cat | I166: Dental | J166: /en/dental-clinic/al-ghubra | K166: =ROUND((IF(E166="Transactional",5,IF(E166="Commercial",4,IF(E166="Comparison",3,IF(E166="Informational",2,3))))*LOG10(IF(ISNUMBER(L166),L166,IFERROR(VALUE(LEFT(F166,FIND("-",F166)-1)),100))+1))/IF(IF(ISBLANK(M166),G166,M166)="High",5,IF(IF(ISBLANK(M166),G166,M166)="Medium",3,1)),2) -> 6.45 | O166: Not Started | P166: long-tail با رقابت پایین
A167: 166 | B167: 2 | C167: AR | D167: عيادة أسنان الغبرة | E167: Commercial | F167: 40-100 | G167: Low | H167: Loc+Cat | I167: Dental | J167: /ar/dental-clinic/al-ghubra | K167: =ROUND((IF(E167="Transactional",5,IF(E167="Commercial",4,IF(E167="Comparison",3,IF(E167="Informational",2,3))))*LOG10(IF(ISNUMBER(L167),L167,IFERROR(VALUE(LEFT(F167,FIND("-",F167)-1)),100))+1))/IF(IF(ISBLANK(M167),G167,M167)="High",5,IF(IF(ISBLANK(M167),G167,M167)="Medium",3,1)),2) -> 6.45 | O167: Not Started
A168: 167 | B168: 2 | C168: EN | D168: Dental Clinic Ruwi | E168: Commercial | F168: 40-100 | G168: Low | H168: Loc+Cat | I168: Dental | J168: /en/dental-clinic/ruwi | K168: =ROUND((IF(E168="Transactional",5,IF(E168="Commercial",4,IF(E168="Comparison",3,IF(E168="Informational",2,3))))*LOG10(IF(ISNUMBER(L168),L168,IFERROR(VALUE(LEFT(F168,FIND("-",F168)-1)),100))+1))/IF(IF(ISBLANK(M168),G168,M168)="High",5,IF(IF(ISBLANK(M168),G168,M168)="Medium",3,1)),2) -> 6.45 | O168: Not Started | P168: long-tail با رقابت پایین
...

Sheet ۰۲_Categories
A1: # | B1: English Name | C1: Arabic Name | D1: Slug | E1: Cluster | F1: Intensity | G1: URL Pattern
A2: 1 | B2: Dentist | C2: طبيب أسنان | D2: dentist | E2: Dental | F2: 5 | G2: /[lang]/dentist
A3: 2 | B3: Dental Clinic | C3: عيادة أسنان | D3: dental-clinic | E3: Dental | F3: 5 | G3: /[lang]/dental-clinic
A4: 3 | B4: Orthodontist | C4: تقويم الأسنان | D4: orthodontist | E4: Dental | F4: 4 | G4: /[lang]/orthodontist
A5: 4 | B5: Endodontist | C5: علاج جذور الأسنان | D5: endodontist | E5: Dental | F5: 3 | G5: /[lang]/endodontist
A6: 5 | B6: Periodontist | C6: أمراض اللثة | D6: periodontist | E6: Dental | F6: 3 | G6: /[lang]/periodontist
A7: 6 | B7: Oral Surgeon | C7: جراحة الفم | D7: oral-surgeon | E7: Dental | F7: 3 | G7: /[lang]/oral-surgeon
A8: 7 | B8: Cosmetic Dentist | C8: تجميل الأسنان | D8: cosmetic-dentist | E8: Dental | F8: 4 | G8: /[lang]/cosmetic-dentist
A9: 8 | B9: Pediatric Dentist | C9: طبيب أسنان أطفال | D9: pediatric-dentist | E9: Dental | F9: 4 | G9: /[lang]/pediatric-dentist
A10: 9 | B10: Dental Implant | C10: زرع الأسنان | D10: dental-implant | E10: Dental | F10: 5 | G10: /[lang]/dental-implant
A11: 10 | B11: Teeth Whitening | C11: تبييض الأسنان | D11: teeth-whitening | E11: Dental | F11: 4 | G11: /[lang]/teeth-whitening
A12: 11 | B12: Invisalign | C12: تقويم شفاف | D12: invisalign | E12: Dental | F12: 4 | G12: /[lang]/invisalign
A13: 12 | B13: Veneers | C13: عدسات الأسنان | D13: veneers | E13: Dental | F13: 4 | G13: /[lang]/veneers
... A107: 106 | B107: Telemedicine | C107: طب عن بعد | D107: telemedicine | E107: Telehealth | F107: 3 | G107: /[lang]/telemedicine

Sheet ۰۳_Locations
A1: # | B1: English Name | C1: Arabic Name | D1: City/Region | E1: Priority | F1: URL Slug
A2: 1 | B2: Al Mouj | C2: الموج | D2: Muscat | E2: 5 | F2: al-mouj
A3: 2 | B3: Al Qurum | C3: القرم | D3: Muscat | E3: 5 | F3: al-qurum
A4: 3 | B4: Al Khuwair | C4: الخوير | D4: Muscat | E4: 5 | F4: al-khuwair
A5: 4 | B5: Madinat Sultan Qaboos | C5: مدينة السلطان قابوس | D5: Muscat | E5: 4 | F5: madinat-sultan-qaboos
A6: 5 | B6: Al Ghubra | C6: الغبرة | D6: Muscat | E6: 4 | F6: al-ghubra
A7: 6 | B7: Ruwi | C7: روي | D7: Muscat | E7: 4 | F7: ruwi
A8: 7 | B8: Bawshar | C8: بوشر | D8: Muscat | E8: 4 | F8: bawshar
A9: 8 | B9: Al Khoud | C9: الخوض | D9: Muscat | E9: 4 | F9: al-khoud
A10: 9 | B10: Al Seeb | C10: السيب | D10: Muscat | E10: 4 | F10: al-seeb
A11: 10 | B11: Mawaleh | C11: الموالح | D11: Muscat | E11: 3 | F11: mawaleh
A12: 11 | B12: Al Hail | C12: الحيل | D12: Muscat | E12: 3 | F12: al-hail
A13: 12 | B13: Al Amerat | C13: العامرات | D13: Muscat | E13: 3 | F13: al-amerat
... A24: 23 | B24: Rustaq | C24: الرستاق | D24: Al Batinah | E24: 2 | F24: rustaq

Sheet ۰۴_Tier1_Money
A1: # | B1: Tier | C1: Lang | D1: Keyword | E1: Intent | F1: Est. Volume | G1: Est. Comp. | H1: Pattern | I1: Cluster | J1: Target URL | K1: Priority | L1: Actual Vol. | M1: Actual Diff. | N1: Current Rank | O1: Status | P1: Notes
A2: 1 | B2: 1 | C2: EN | D2: best Dentist Muscat | E2: Commercial | F2: 1000-2500 | G2: High | H2: Money-City | I2: Dental | J2: /en/dentist | K2: =ROUND((IF(E2="Transactional",5,IF(E2="Commercial",4,IF(E2="Comparison",3,IF(E2="Informational",2,3))))*LOG10(IF(ISNUMBER(L2),L2,IFERROR(VALUE(LEFT(F2,FIND("-",F2)-1)),100))+1))/IF(IF(ISBLANK(M2),G2,M2)="High",5,IF(IF(ISBLANK(M2),G2,M2)="Medium",3,1)),2) -> 2.4 | O2: Not Started | P2: بهترین Dentist در مسقط — کلمه پربازدید
A3: 2 | B3: 1 | C3: AR | D3: أفضل طبيب أسنان مسقط | E3: Commercial | F3: 800-2000 | G3: High | H3: Money-City | I3: Dental | J3: /ar/dentist | K3: =ROUND((IF(E3="Transactional",5,IF(E3="Commercial",4,IF(E3="Comparison",3,IF(E3="Informational",2,3))))*LOG10(IF(ISNUMBER(L3),L3,IFERROR(VALUE(LEFT(F3,FIND("-",F3)-1)),100))+1))/IF(IF(ISBLANK(M3),G3,M3)="High",5,IF(IF(ISBLANK(M3),G3,M3)="Medium",3,1)),2) -> 2.32 | O3: Not Started | P3: رقابت کم‌تر در عربی، اولویت بالاتر
A4: 3 | B4: 1 | C4: EN | D4: best Dental Clinic Muscat | E4: Commercial | F4: 1000-2500 | G4: High | H4: Money-City | I4: Dental | J4: /en/dental-clinic | K4: =ROUND((IF(E4="Transactional",5,IF(E4="Commercial",4,IF(E4="Comparison",3,IF(E4="Informational",2,3))))*LOG10(IF(ISNUMBER(L4),L4,IFERROR(VALUE(LEFT(F4,FIND("-",F4)-1)),100))+1))/IF(IF(ISBLANK(M4),G4,M4)="High",5,IF(IF(ISBLANK(M4),G4,M4)="Medium",3,1)),2) -> 2.4 | O4: Not Started | P4: بهترین Dental Clinic در مسقط — کلمه پربازدید
A5: 4 | B5: 1 | C5: AR | D5: أفضل عيادة أسنان مسقط | E5: Commercial | F5: 800-2000 | G5: High | H5: Money-City | I5: Dental | J5: /ar/dental-clinic | K5: =ROUND((IF(E5="Transactional",5,IF(E5="Commercial",4,IF(E5="Comparison",3,IF(E5="Informational",2,3))))*LOG10(IF(ISNUMBER(L5),L5,IFERROR(VALUE(LEFT(F5,FIND("-",F5)-1)),100))+1))/IF(IF(ISBLANK(M5),G5,M5)="High",5,IF(IF(ISBLANK(M5),G5,M5)="Medium",3,1)),2) -> 2.32 | O5: Not Started | P5: رقابت کم‌تر در عربی، اولویت بالاتر
A6: 5 | B6: 1 | C6: EN | D6: best Orthodontist Muscat | E6: Commercial | F6: 400-1000 | G6: Medium | H6: Money-City | I6: Dental | J6: /en/orthodontist | K6: =ROUND((IF(E6="Transactional",5,IF(E6="Commercial",4,IF(E6="Comparison",3,IF(E6="Informational",2,3))))*LOG10(IF(ISNUMBER(L6),L6,IFERROR(VALUE(LEFT(F6,FIND("-",F6)-1)),100))+1))/IF(IF(ISBLANK(M6),G6,M6)="High",5,IF(IF(ISBLANK(M6),G6,M6)="Medium",3,1)),2) -> 3.47 | O6: Not Started | P6: بهترین Orthodontist در مسقط — کلمه پربازدید
A7: 6 | B7: 1 | C7: AR | D7: أفضل تقويم الأسنان مسقط | E7: Commercial | F7: 350-800 | G7: Medium | H7: Money-City | I7: Dental | J7: /ar/orthodontist | K7: =ROUND((IF(E7="Transactional",5,IF(E7="Commercial",4,IF(E7="Comparison",3,IF(E7="Informational",2,3))))*LOG10(IF(ISNUMBER(L7),L7,IFERROR(VALUE(LEFT(F7,FIND("-",F7)-1)),100))+1))/IF(IF(ISBLANK(M7),G7,M7)="High",5,IF(IF(ISBLANK(M7),G7,M7)="Medium",3,1)),2) -> 3.39 | O7: Not Started | P7: رقابت کم‌تر در عربی، اولویت بالاتر
A8: 7 | B8: 1 | C8: EN | D8: best Cosmetic Dentist Muscat | E8: Commercial | F8: 400-1000 | G8: Medium | H8: Money-City | I8: Dental | J8: /en/cosmetic-dentist | K8: =ROUND((IF(E8="Transactional",5,IF(E8="Commercial",4,IF(E8="Comparison",3,IF(E8="Informational",2,3))))*LOG10(IF(ISNUMBER(L8),L8,IFERROR(VALUE(LEFT(F8,FIND("-",F8)-1)),100))+1))/IF(IF(ISBLANK(M8),G8,M8)="High",5,IF(IF(ISBLANK(M8),G8,M8)="Medium",3,1)),2) -> 3.47 | O8: Not Started | P8: بهترین Cosmetic Dentist در مسقط — کلمه پربازدید
A9: 8 | B9: 1 | C9: AR | D9: أفضل تجميل الأسنان مسقط | E9: Commercial | F9: 350-800 | G9: Medium | H9: Money-City | I9: Dental | J9: /ar/cosmetic-dentist | K9: =ROUND((IF(E9="Transactional",5,IF(E9="Commercial",4,IF(E9="Comparison",3,IF(E9="Informational",2,3))))*LOG10(IF(ISNUMBER(L9),L9,IFERROR(VALUE(LEFT(F9,FIND("-",F9)-1)),100))+1))/IF(IF(ISBLANK(M9),G9,M9)="High",5,IF(IF(ISBLANK(M9),G9,M9)="Medium",3,1)),2) -> 3.39 | O9: Not Started | P9: رقابت کم‌تر در عربی، اولویت بالاتر
A10: 9 | B10: 1 | C10: EN | D10: best Pediatric Dentist Muscat | E10: Commercial | F10: 400-1000 | G10: Medium | H10: Money-City | I10: Dental | J10: /en/pediatric-dentist | K10: =ROUND((IF(E10="Transactional",5,IF(E10="Commercial",4,IF(E10="Comparison",3,IF(E10="Informational",2,3))))*LOG10(IF(ISNUMBER(L10),L10,IFERROR(VALUE(LEFT(F10,FIND("-",F10)-1)),100))+1))/IF(IF(ISBLANK(M10),G10,M10)="High",5,IF(IF(ISBLANK(M10),G10,M10)="Medium",3,1)),2) -> 3.47 | O10: Not Started | P10: بهترین Pediatric Dentist در مسقط — کلمه پربازدید
A11: 10 | B11: 1 | C11: AR | D11: أفضل طبيب أسنان أطفال مسقط | E11: Commercial | F11: 350-800 | G11: Medium | H11: Money-City | I11: Dental | J11: /ar/pediatric-dentist | K11: =ROUND((IF(E11="Transactional",5,IF(E11="Commercial",4,IF(E11="Comparison",3,IF(E11="Informational",2,3))))*LOG10(IF(ISNUMBER(L11),L11,IFERROR(VALUE(LEFT(F11,FIND("-",F11)-1)),100))+1))/IF(IF(ISBLANK(M11),G11,M11)="High",5,IF(IF(ISBLANK(M11),G11,M11)="Medium",3,1)),2) -> 3.39 | O11: Not Started | P11: رقابت کم‌تر در عربی، اولویت بالاتر
A12: 11 | B12: 1 | C12: EN | D12: best Dental Implant Muscat | E12: Commercial | F12: 1000-2500 | G12: High | H12: Money-City | I12: Dental | J12: /en/dental-implant | K12: =ROUND((IF(E12="Transactional",5,IF(E12="Commercial",4,IF(E12="Comparison",3,IF(E12="Informational",2,3))))*LOG10(IF(ISNUMBER(L12),L12,IFERROR(VALUE(LEFT(F12,FIND("-",F12)-1)),100))+1))/IF(IF(ISBLANK(M12),G12,M12)="High",5,IF(IF(ISBLANK(M12),G12,M12)="Medium",3,1)),2) -> 2.4 | O12: Not Started | P12: بهترین Dental Implant در مسقط — کلمه پربازدید
A13: 12 | B13: 1 | C13: AR | D13: أفضل زرع الأسنان مسقط | E13: Commercial | F13: 800-2000 | G13: High | H13: Money-City | I13: Dental | J13: /ar/dental-implant | K13: =ROUND((IF(E13="Transactional",5,IF(E13="Commercial",4,IF(E13="Comparison",3,IF(E13="Informational",2,3))))*LOG10(IF(ISNUMBER(L13),L13,IFERROR(VALUE(LEFT(F13,FIND("-",F13)-1)),100))+1))/IF(IF(ISBLANK(M13),G13,M13)="High",5,IF(IF(ISBLANK(M13),G13,M13)="Medium",3,1)),2) -> 2.32 | O13: Not Started | P13: رقابت کم‌تر در عربی، اولویت بالاتر
... A141: 140 | B141: 1 | C141: AR | D141: أفضل رعاية منزلية مسقط | E141: Commercial | F141: 350-800 | G141: Medium | H141: Money-City | I141: Home | J141: /ar/home-healthcare | K141: =ROUND((IF(E141="Transactional",5,IF(E141="Commercial",4,IF(E141="Comparison",3,IF(E141="Informational",2,3))))*LOG10(IF(ISNUMBER(L141),L141,IFERROR(VALUE(LEFT(F141,FIND("-",F141)-1)),100))+1))/IF(IF(ISBLANK(M141),G141,M141)="High",5,IF(IF(ISBLANK(M141),G141,M141)="Medium",3,1)),2) -> 3.39 | O141: Not Started | P141: رقابت کم‌تر در عربی، اولویت بالاتر

Sheet ۰۵_Tier2_Programmatic
A1: # | B1: Tier | C1: Lang | D1: Keyword | E1: Intent | F1: Est. Volume | G1: Est. Comp. | H1: Pattern | I1: Cluster | J1: Target URL | K1: Priority | L1: Actual Vol. | M1: Actual Diff. | N1: Current Rank | O1: Status | P1: Notes
A2: 141 | B2: 2 | C2: EN | D2: Dentist Al Mouj | E2: Commercial | F2: 40-100 | G2: Low | H2: Loc+Cat | I2: Dental | J2: /en/dentist/al-mouj | K2: =ROUND((IF(E2="Transactional",5,IF(E2="Commercial",4,IF(E2="Comparison",3,IF(E2="Informational",2,3))))*LOG10(IF(ISNUMBER(L2),L2,IFERROR(VALUE(LEFT(F2,FIND("-",F2)-1)),100))+1))/IF(IF(ISBLANK(M2),G2,M2)="High",5,IF(IF(ISBLANK(M2),G2,M2)="Medium",3,1)),2) -> 6.45 | O2: Not Started | P2: long-tail با رقابت پایین
A3: 142 | B3: 2 | C3: AR | D3: طبيب أسنان الموج | E3: Commercial | F3: 40-100 | G3: Low | H3: Loc+Cat | I3: Dental | J3: /ar/dentist/al-mouj | K3: =ROUND((IF(E3="Transactional",5,IF(E3="Commercial",4,IF(E3="Comparison",3,IF(E3="Informational",2,3))))*LOG10(IF(ISNUMBER(L3),L3,IFERROR(VALUE(LEFT(F3,FIND("-",F3)-1)),100))+1))/IF(IF(ISBLANK(M3),G3,M3)="High",5,IF(IF(ISBLANK(M3),G3,M3)="Medium",3,1)),2) -> 6.45 | O3: Not Started
A4: 143 | B4: 2 | C4: EN | D4: Dentist Al Qurum | E4: Commercial | F4: 40-100 | G4: Low | H4: Loc+Cat | I4: Dental | J4: /en/dentist/al-qurum | K4: =ROUND((IF(E4="Transactional",5,IF(E4="Commercial",4,IF(E4="Comparison",3,IF(E4="Informational",2,3))))*LOG10(IF(ISNUMBER(L4),L4,IFERROR(VALUE(LEFT(F4,FIND("-",F4)-1)),100))+1))/IF(IF(ISBLANK(M4),G4,M4)="High",5,IF(IF(ISBLANK(M4),G4,M4)="Medium",3,1)),2) -> 6.45 | O4: Not Started | P4: long-tail با رقابت پایین
A5: 144 | B5: 2 | C5: AR | D5: طبيب أسنان القرم | E5: Commercial | F5: 40-100 | G5: Low | H5: Loc+Cat | I5: Dental | J5: /ar/dentist/al-qurum | K5: =ROUND((IF(E5="Transactional",5,IF(E5="Commercial",4,IF(E5="Comparison",3,IF(E5="Informational",2,3))))*LOG10(IF(ISNUMBER(L5),L5,IFERROR(VALUE(LEFT(F5,FIND("-",F5)-1)),100))+1))/IF(IF(ISBLANK(M5),G5,M5)="High",5,IF(IF(ISBLANK(M5),G5,M5)="Medium",3,1)),2) -> 6.45 | O5: Not Started
A6: 145 | B6: 2 | C6: EN | D6: Dentist Al Khuwair | E6: Commercial | F6: 40-100 | G6: Low | H6: Loc+Cat | I6: Dental | J6: /en/dentist/al-khuwair | K6: =ROUND((IF(E6="Transactional",5,IF(E6="Commercial",4,IF(E6="Comparison",3,IF(E6="Informational",2,3))))*LOG10(IF(ISNUMBER(L6),L6,IFERROR(VALUE(LEFT(F6,FIND("-",F6)-1)),100))+1))/IF(IF(ISBLANK(M6),G6,M6)="High",5,IF(IF(ISBLANK(M6),G6,M6)="Medium",3,1)),2) -> 6.45 | O6: Not Started | P6: long-tail با رقابت پایین
A7: 146 | B7: 2 | C7: AR | D7: طبيب أسنان الخوير | E7: Commercial | F7: 40-100 | G7: Low | H7: Loc+Cat | I7: Dental | J7: /ar/dentist/al-khuwair | K7: =ROUND((IF(E7="Transactional",5,IF(E7="Commercial",4,IF(E7="Comparison",3,IF(E7="Informational",2,3))))*LOG10(IF(ISNUMBER(L7),L7,IFERROR(VALUE(LEFT(F7,FIND("-",F7)-1)),100))+1))/IF(IF(ISBLANK(M7),G7,M7)="High",5,IF(IF(ISBLANK(M7),G7,M7)="Medium",3,1)),2) -> 6.45 | O7: Not Started
A8: 147 | B8: 2 | C8: EN | D8: Dentist Madinat Sultan Qaboos | E8: Commercial | F8: 40-100 | G8: Low | H8: Loc+Cat | I8: Dental | J8: /en/dentist/madinat-sultan-qaboos | K8: =ROUND((IF(E8="Transactional",5,IF(E8="Commercial",4,IF(E8="Comparison",3,IF(E8="Informational",2,3))))*LOG10(IF(ISNUMBER(L8),L8,IFERROR(VALUE(LEFT(F8,FIND("-",F8)-1)),100))+1))/IF(IF(ISBLANK(M8),G8,M8)="High",5,IF(IF(ISBLANK(M8),G8,M8)="Medium",3,1)),2) -> 6.45 | O8: Not Started | P8: long-tail با رقابت پایین
A9: 148 | B9: 2 | C9: AR | D9: طبيب أسنان مدينة السلطان قابوس | E9: Commercial | F9: 40-100 | G9: Low | H9: Loc+Cat | I9: Dental | J9: /ar/dentist/madinat-sultan-qaboos | K9: =ROUND((IF(E9="Transactional",5,IF(E9="Commercial",4,IF(E9="Comparison",3,IF(E9="Informational",2,3))))*LOG10(IF(ISNUMBER(L9),L9,IFERROR(VALUE(LEFT(F9,FIND("-",F9)-1)),100))+1))/IF(IF(ISBLANK(M9),G9,M9)="High",5,IF(IF(ISBLANK(M9),G9,M9)="Medium",3,1)),2) -> 6.45 | O9: Not Started
A10: 149 | B10: 2 | C10: EN | D10: Dentist Al Ghubra | E10: Commercial | F10: 40-100 | G10: Low | H10: Loc+Cat | I10: Dental | J10: /en/dentist/al-ghubra | K10: =ROUND((IF(E10="Transactional",5,IF(E10="Commercial",4,IF(E10="Comparison",3,IF(E10="Informational",2,3))))*LOG10(IF(ISNUMBER(L10),L10,IFERROR(VALUE(LEFT(F10,FIND("-",F10)-1)),100))+1))/IF(IF(ISBLANK(M10),G10,M10)="High",5,IF(IF(ISBLANK(M10),G10,M10)="Medium",3,1)),2) -> 6.45 | O10: Not Started | P10: long-tail با رقابت پایین
A11: 150 | B11: 2 | C11: AR | D11: طبيب أسنان الغبرة | E11: Commercial | F11: 40-100 | G11: Low | H11: Loc+Cat | I11: Dental | J11: /ar/dentist/al-ghubra | K11: =ROUND((IF(E11="Transactional",5,IF(E11="Commercial",4,IF(E11="Comparison",3,IF(E11="Informational",2,3))))*LOG10(IF(ISNUMBER(L11),L11,IFERROR(VALUE(LEFT(F11,FIND("-",F11)-1)),100))+1))/IF(IF(ISBLANK(M11),G11,M11)="High",5,IF(IF(ISBLANK(M11),G11,M11)="Medium",3,1)),2) -> 6.45 | O11: Not Started
A12: 151 | B12: 2 | C12: EN | D12: Dentist Ruwi | E12: Commercial | F12: 40-100 | G12: Low | H12: Loc+Cat | I12: Dental | J12: /en/dentist/ruwi | K12: =ROUND((IF(E12="Transactional",5,IF(E12="Commercial",4,IF(E12="Comparison",3,IF(E12="Informational",2,3))))*LOG10(IF(ISNUMBER(L12),L12,IFERROR(VALUE(LEFT(F12,FIND("-",F12)-1)),100))+1))/IF(IF(ISBLANK(M12),G12,M12)="High",5,IF(IF(ISBLANK(M12),G12,M12)="Medium",3,1)),2) -> 6.45 | O12: Not Started | P12: long-tail با رقابت پایین
A13: 152 | B13: 2 | C13: AR | D13: طبيب أسنان روي | E13: Commercial | F13: 40-100 | G13: Low | H13: Loc+Cat | I13: Dental | J13: /ar/dentist/ruwi | K13: =ROUND((IF(E13="Transactional",5,IF(E13="Commercial",4,IF(E13="Comparison",3,IF(E13="Informational",2,3))))*LOG10(IF(ISNUMBER(L13),L13,IFERROR(VALUE(LEFT(F13,FIND("-",F13)-1)),100))+1))/IF(IF(ISBLANK(M13),G13,M13)="High",5,IF(IF(ISBLANK(M13),G13,M13)="Medium",3,1)),2) -> 6.45 | O13: Not Started
A14: 153 | B14: 2 | C14: EN | D14: Dentist Bawshar | E14: Commercial | F14: 40-100 | G14: Low | H14: Loc+Cat | I14: Dental | J14: /en/dentist/bawshar | K14: =ROUND((IF(E14="Transactional",5,IF(E14="Commercial",4,IF(E14="Comparison",3,IF(E14="Informational",2,3))))*LOG10(IF(ISNUMBER(L14),L14,IFERROR(VALUE(LEFT(F14,FIND("-",F14)-1)),100))+1))/IF(IF(ISBLANK(M14),G14,M14)="High",5,IF(IF(ISBLANK(M14),G14,M14)="Medium",3,1)),2) -> 6.45 | O14: Not Started | P14: long-tail با رقابت پایین
A15: 154 | B15: 2 | C15: AR | D15: طبيب أسنان بوشر | E15: Commercial | F15: 40-100 | G15: Low | H15: Loc+Cat | I15: Dental | J15: /ar/dentist/bawshar | K15: =ROUND((IF(E15="Transactional",5,IF(E15="Commercial",4,IF(E15="Comparison",3,IF(E15="Informational",2,3))))*LOG10(IF(ISNUMBER(L15),L15,IFERROR(VALUE(LEFT(F15,FIND("-",F15)-1)),100))+1))/IF(IF(ISBLANK(M15),G15,M15)="High",5,IF(IF(ISBLANK(M15),G15,M15)="Medium",3,1)),2) -> 6.45 | O15: Not Started
A16: 155 | B16: 2 | C16: EN | D16: Dentist Al Khoud | E16: Commercial | F16: 40-100 | G16: Low | H16: Loc+Cat | I16: Dental | J16: /en/dentist/al-khoud | K16: =ROUND((IF(E16="Transactional",5,IF(E16="Commercial",4,IF(E16="Comparison",3,IF(E16="Informational",2,3))))*LOG10(IF(ISNUMBER(L16),L16,IFERROR(VALUE(LEFT(F16,FIND("-",F16)-1)),100))+1))/IF(IF(ISBLANK(M16),G16,M16)="High",5,IF(IF(ISBLANK(M16),G16,M16)="Medium",3,1)),2) -> 6.45 | O16: Not Started | P16: long-tail با رقابت پایین
A17: 156 | B17: 2 | C17: AR | D17: طبيب أسنان الخوض | E17: Commercial | F17: 40-100 | G17: Low | H17: Loc+Cat | I17: Dental | J17: /ar/dentist/al-khoud | K17: =ROUND((IF(E17="Transactional",5,IF(E17="Commercial",4,IF(E17="Comparison",3,IF(E17="Informational",2,3))))*LOG10(IF(ISNUMBER(L17),L17,IFERROR(VALUE(LEFT(F17,FIND("-",F17)-1)),100))+1))/IF(IF(ISBLANK(M17),G17,M17)="High",5,IF(IF(ISBLANK(M17),G17,M17)="Medium",3,1)),2) -> 6.45 | O17: Not Started
A18: 157 | B18: 2 | C18: EN | D18: Dental Clinic Al Mouj | E18: Commercial | F18: 40-100 | G18: Low | H18: Loc+Cat | I18: Dental | J18: /en/dental-clinic/al-mouj | K18: =ROUND((IF(E18="Transactional",5,IF(E18="Commercial",4,IF(E18="Comparison",3,IF(E18="Informational",2,3))))*LOG10(IF(ISNUMBER(L18),L18,IFERROR(VALUE(LEFT(F18,FIND("-",F18)-1)),100))+1))/IF(IF(ISBLANK(M18),G18,M18)="High",5,IF(IF(ISBLANK(M18),G18,M18)="Medium",3,1)),2) -> 6.45 | O18: Not Started | P18: long-tail با رقابت پایین
A19: 158 | B19: 2 | C19: AR | D19: عيادة أسنان الموج | E19: Commercial | F19: 40-100 | G19: Low | H19: Loc+Cat | I19: Dental | J19: /ar/dental-clinic/al-mouj | K19: =ROUND((IF(E19="Transactional",5,IF(E19="Commercial",4,IF(E19="Comparison",3,IF(E19="Informational",2,3))))*LOG10(IF(ISNUMBER(L19),L19,IFERROR(VALUE(LEFT(F19,FIND("-",F19)-1)),100))+1))/IF(IF(ISBLANK(M19),G19,M19)="High",5,IF(IF(ISBLANK(M19),G19,M19)="Medium",3,1)),2) -> 6.45 | O19: Not Started
A20: 159 | B20: 2 | C20: EN | D20: Dental Clinic Al Qurum | E20: Commercial | F20: 40-100 | G20: Low | H20: Loc+Cat | I20: Dental | J20: /en/dental-clinic/al-qurum | K20: =ROUND((IF(E20="Transactional",5,IF(E20="Commercial",4,IF(E20="Comparison",3,IF(E20="Informational",2,3))))*LOG10(IF(ISNUMBER(L20),L20,IFERROR(VALUE(LEFT(F20,FIND("-",F20)-1)),100))+1))/IF(IF(ISBLANK(M20),G20,M20)="High",5,IF(IF(ISBLANK(M20),G20,M20)="Medium",3,1)),2) -> 6.45 | O20: Not Started | P20: long-tail با رقابت پایین
A21: 160 | B21: 2 | C21: AR | D21: عيادة أسنان القرم | E21: Commercial | F21: 40-100 | G21: Low | H21: Loc+Cat | I21: Dental | J21: /ar/dental-clinic/al-qurum | K21: =ROUND((IF(E21="Transactional",5,IF(E21="Commercial",4,IF(E21="Comparison",3,IF(E21="Informational",2,3))))*LOG10(IF(ISNUMBER(L21),L21,IFERROR(VALUE(LEFT(F21,FIND("-",F21)-1)),100))+1))/IF(IF(ISBLANK(M21),G21,M21)="High",5,IF(IF(ISBLANK(M21),G21,M21)="Medium",3,1)),2) -> 6.45 | O21: Not Started
A22: 161 | B22: 2 | C22: EN | D22: Dental Clinic Al Khuwair | E22: Commercial | F22: 40-100 | G22: Low | H22: Loc+Cat | I22: Dental | J22: /en/dental-clinic/al-khuwair | K22: =ROUND((IF(E22="Transactional",5,IF(E22="Commercial",4,IF(E22="Comparison",3,IF(E22="Informational",2,3))))*LOG10(IF(ISNUMBER(L22),L22,IFERROR(VALUE(LEFT(F22,FIND("-",F22)-1)),100))+1))/IF(IF(ISBLANK(M22),G22,M22)="High",5,IF(IF(ISBLANK(M22),G22,M22)="Medium",3,1)),2) -> 6.45 | O22: Not Started | P22: long-tail با رقابت پایین
A23: 162 | B23: 2 | C23: AR | D23: عيادة أسنان الخوير | E23: Commercial | F23: 40-100 | G23: Low | H23: Loc+Cat | I23: Dental | J23: /ar/dental-clinic/al-khuwair | K23: =ROUND((IF(E23="Transactional",5,IF(E23="Commercial",4,IF(E23="Comparison",3,IF(E23="Informational",2,3))))*LOG10(IF(ISNUMBER(L23),L23,IFERROR(VALUE(LEFT(F23,FIND("-",F23)-1)),100))+1))/IF(IF(ISBLANK(M23),G23,M23)="High",5,IF(IF(ISBLANK(M23),G23,M23)="Medium",3,1)),2) -> 6.45 | O23: Not Started
A24: 163 | B24: 2 | C24: EN | D24: Dental Clinic Madinat Sultan Qaboos | E24: Commercial | F24: 40-100 | G24: Low | H24: Loc+Cat | I24: Dental | J24: /en/dental-clinic/madinat-sultan-qaboos | K24: =ROUND((IF(E24="Transactional",5,IF(E24="Commercial",4,IF(E24="Comparison",3,IF(E24="Informational",2,3))))*LOG10(IF(ISNUMBER(L24),L24,IFERROR(VALUE(LEFT(F24,FIND("-",F24)-1)),100))+1))/IF(IF(ISBLANK(M24),G24,M24)="High",5,IF(IF(ISBLANK(M24),G24,M24)="Medium",3,1)),2) -> 6.45 | O24: Not Started | P24: long-tail با رقابت پایین
A25: 164 | B25: 2 | C25: AR | D25: عيادة أسنان مدينة السلطان قابوس | E25: Commercial | F25: 40-100 | G25: Low | H25: Loc+Cat | I25: Dental | J25: /ar/dental-clinic/madinat-sultan-qaboos | K25: =ROUND((IF(E25="Transactional",5,IF(E25="Commercial",4,IF(E25="Comparison",3,IF(E25="Informational",2,3))))*LOG10(IF(ISNUMBER(L25),L25,IFERROR(VALUE(LEFT(F25,FIND("-",F25)-1)),100))+1))/IF(IF(ISBLANK(M25),G25,M25)="High",5,IF(IF(ISBLANK(M25),G25,M25)="Medium",3,1)),2) -> 6.45 | O25: Not Started
A26: 165 | B26: 2 | C26: EN | D26: Dental Clinic Al Ghubra | E26: Commercial | F26: 40-100 | G26: Low | H26: Loc+Cat | I26: Dental | J26: /en/dental-clinic/al-ghubra | K26: =ROUND((IF(E26="Transactional",5,IF(E26="Commercial",4,IF(E26="Comparison",3,IF(E26="Informational",2,3))))*LOG10(IF(ISNUMBER(L26),L26,IFERROR(VALUE(LEFT(F26,FIND("-",F26)-1)),100))+1))/IF(IF(ISBLANK(M26),G26,M26)="High",5,IF(IF(ISBLANK(M26),G26,M26)="Medium",3,1)),2) -> 6.45 | O26: Not Started | P26: long-tail با رقابت پایین
A27: 166 | B27: 2 | C27: AR | D27: عيادة أسنان الغبرة | E27: Commercial | F27: 40-100 | G27: Low | H27: Loc+Cat | I27: Dental | J27: /ar/dental-clinic/al-ghubra | K27: =ROUND((IF(E27="Transactional",5,IF(E27="Commercial",4,IF(E27="Comparison",3,IF(E27="Informational",2,3))))*LOG10(IF(ISNUMBER(L27),L27,IFERROR(VALUE(LEFT(F27,FIND("-",F27)-1)),100))+1))/IF(IF(ISBLANK(M27),G27,M27)="High",5,IF(IF(ISBLANK(M27),G27,M27)="Medium",3,1)),2) -> 6.45 | O27: Not Started
A28: 167 | B28: 2 | C28: EN | D28: Dental Clinic Ruwi | E28: Commercial | F28: 40-100 | G28: Low | H28: Loc+Cat | I28: Dental | J28: /en/dental-clinic/ruwi | K28: =ROUND((IF(E28="Transactional",5,IF(E28="Commercial",4,IF(E28="Comparison",3,IF(E28="Informational",2,3))))*LOG10(IF(ISNUMBER(L28),L28,IFERROR(VALUE(LEFT(F28,FIND("-",F28)-1)),100))+1))/IF(IF(ISBLANK(M28),G28,M28)="High",5,IF(IF(ISBLANK(M28),G28,M28)="Medium",3,1)),2) -> 6.45 | O28: Not Started | P28: long-tail با رقابت پایین
A29: 168 | B29: 2 | C29: AR | D29: عيادة أسنان روي | E29: Commercial | F29: 40-100 | G29: Low | H29: Loc+Cat | I29: Dental | J29: /ar/dental-clinic/ruwi | K29: =ROUND((IF(E29="Transactional",5,IF(E29="Commercial",4,IF(E29="Comparison",3,IF(E29="Informational",2,3))))*LOG10(IF(ISNUMBER(L29),L29,IFERROR(VALUE(LEFT(F29,FIND("-",F29)-1)),100))+1))/IF(IF(ISBLANK(M29),G29,M29)="High",5,IF(IF(ISBLANK(M29),G29,M29)="Medium",3,1)),2) -> 6.45 | O29: Not Started
A30: 169 | B30: 2 | C30: EN | D30: Dental Clinic Bawshar | E30: Commercial | F30: 40-100 | G30: Low | H30: Loc+Cat | I30: Dental | J30: /en/dental-clinic/bawshar | K30: =ROUND((IF(E30="Transactional",5,IF(E30="Commercial",4,IF(E30="Comparison",3,IF(E30="Informational",2,3))))*LOG10(IF(ISNUMBER(L30),L30,IFERROR(VALUE(LEFT(F30,FIND("-",F30)-1)),100))+1))/IF(IF(ISBLANK(M30),G30,M30)="High",5,IF(IF(ISBLANK(M30),G30,M30)="Medium",3,1)),2) -> 6.45 | O30: Not Started | P30: long-tail با رقابت پایین
A31: 170 | B31: 2 | C31: AR | D31: عيادة أسنان بوشر | E31: Commercial | F31: 40-100 | G31: Low | H31: Loc+Cat | I31: Dental | J31: /ar/dental-clinic/bawshar | K31: =ROUND((IF(E31="Transactional",5,IF(E31="Commercial",4,IF(E31="Comparison",3,IF(E31="Informational",2,3))))*LOG10(IF(ISNUMBER(L31),L31,IFERROR(VALUE(LEFT(F31,FIND("-",F31)-1)),100))+1))/IF(IF(ISBLANK(M31),G31,M31)="High",5,IF(IF(ISBLANK(M31),G31,M31)="Medium",3,1)),2) -> 6.45 | O31: Not Started
A32: 171 | B32: 2 | C32: EN | D32: Dental Clinic Al Khoud | E32: Commercial | F32: 40-100 | G32: Low | H32: Loc+Cat | I32: Dental | J32: /en/dental-clinic/al-khoud | K32: =ROUND((IF(E32="Transactional",5,IF(E32="Commercial",4,IF(E32="Comparison",3,IF(E32="Informational",2,3))))*LOG10(IF(ISNUMBER(L32),L32,IFERROR(VALUE(LEFT(F32,FIND("-",F32)-1)),100))+1))/IF(IF(ISBLANK(M32),G32,M32)="High",5,IF(IF(ISBLANK(M32),G32,M32)="Medium",3,1)),2) -> 6.45 | O32: Not Started | P32: long-tail با رقابت پایین
A33: 172 | B33: 2 | C33: AR | D33: عيادة أسنان الخوض | E33: Commercial | F33: 40-100 | G33: Low | H33: Loc+Cat | I33: Dental | J33: /ar/dental-clinic/al-khoud | K33: =ROUND((IF(E33="Transactional",5,IF(E33="Commercial",4,IF(E33="Comparison",3,IF(E33="Informational",2,3))))*LOG10(IF(ISNUMBER(L33),L33,IFERROR(VALUE(LEFT(F33,FIND("-",F33)-1)),100))+1))/IF(IF(ISBLANK(M33),G33,M33)="High",5,IF(IF(ISBLANK(M33),G33,M33)="Medium",3,1)),2) -> 6.45 | O33: Not Started
A34: 173 | B34: 2 | C34: EN | D34: Orthodontist Al Mouj | E34: Commercial | F34: 30-80 | G34: Low | H34: Loc+Cat | I34: Dental | J34: /en/orthodontist/al-mouj | K34: =ROUND((IF(E34="Transactional",5,IF(E34="Commercial",4,IF(E34="Comparison",3,IF(E34="Informational",2,3))))*LOG10(IF(ISNUMBER(L34),L34,IFERROR(VALUE(LEFT(F34,FIND("-",F34)-1)),100))+1))/IF(IF(ISBLANK(M34),G34,M34)="High",5,IF(IF(ISBLANK(M34),G34,M34)="Medium",3,1)),2) -> 5.97 | O34: Not Started | P34: long-tail با رقابت پایین
A35: 174 | B35: 2 | C35: AR | D35: تقويم الأسنان الموج | E35: Commercial | F35: 30-80 | G35: Low | H35: Loc+Cat | I35: Dental | J35: /ar/orthodontist/al-mouj | K35: =ROUND((IF(E35="Transactional",5,IF(E35="Commercial",4,IF(E35="Comparison",3,IF(E35="Informational",2,3))))*LOG10(IF(ISNUMBER(L35),L35,IFERROR(VALUE(LEFT(F35,FIND("-",F35)-1)),100))+1))/IF(IF(ISBLANK(M35),G35,M35)="High",5,IF(IF(ISBLANK(M35),G35,M35)="Medium",3,1)),2) -> 5.97 | O35: Not Started
A36: 175 | B36: 2 | C36: EN | D36: Orthodontist Al Qurum | E36: Commercial | F36: 30-80 | G36: Low | H36: Loc+Cat | I36: Dental | J36: /en/orthodontist/al-qurum | K36: =ROUND((IF(E36="Transactional",5,IF(E36="Commercial",4,IF(E36="Comparison",3,IF(E36="Informational",2,3))))*LOG10(IF(ISNUMBER(L36),L36,IFERROR(VALUE(LEFT(F36,FIND("-",F36)-1)),100))+1))/IF(IF(ISBLANK(M36),G36,M36)="High",5,IF(IF(ISBLANK(M36),G36,M36)="Medium",3,1)),2) -> 5.97 | O36: Not Started | P36: long-tail با رقابت پایین
A37: 176 | B37: 2 | C37: AR | D37: تقويم الأسنان القرم | E37: Commercial | F37: 30-80 | G37: Low | H37: Loc+Cat | I37: Dental | J37: /ar/orthodontist/al-qurum | K37: =ROUND((IF(E37="Transactional",5,IF(E37="Commercial",4,IF(E37="Comparison",3,IF(E37="Informational",2,3))))*LOG10(IF(ISNUMBER(L37),L37,IFERROR(VALUE(LEFT(F37,FIND("-",F37)-1)),100))+1))/IF(IF(ISBLANK(M37),G37,M37)="High",5,IF(IF(ISBLANK(M37),G37,M37)="Medium",3,1)),2) -> 5.97 | O37: Not Started
A38: 177 | B38: 2 | C38: EN | D38: Orthodontist Al Khuwair | E38: Commercial | F38: 30-80 | G38: Low | H38: Loc+Cat | I38: Dental | J38: /en/orthodontist/al-khuwair | K38: =ROUND((IF(E38="Transactional",5,IF(E38="Commercial",4,IF(E38="Comparison",3,IF(E38="Informational",2,3))))*LOG10(IF(ISNUMBER(L38),L38,IFERROR(VALUE(LEFT(F38,FIND("-",F38)-1)),100))+1))/IF(IF(ISBLANK(M38),G38,M38)="High",5,IF(IF(ISBLANK(M38),G38,M38)="Medium",3,1)),2) -> 5.97 | O38: Not Started | P38: long-tail با رقابت پایین
A39: 178 | B39: 2 | C39: AR | D39: تقويم الأسنان الخوير | E39: Commercial | F39: 30-80 | G39: Low | H39: Loc+Cat | I39: Dental | J39: /ar/orthodontist/al-khuwair | K39: =ROUND((IF(E39="Transactional",5,IF(E39="Commercial",4,IF(E39="Comparison",3,IF(E39="Informational",2,3))))*LOG10(IF(ISNUMBER(L39),L39,IFERROR(VALUE(LEFT(F39,FIND("-",F39)-1)),100))+1))/IF(IF(ISBLANK(M39),G39,M39)="High",5,IF(IF(ISBLANK(M39),G39,M39)="Medium",3,1)),2) -> 5.97 | O39: Not Started
A40: 179 | B40: 2 | C40: EN | D40: Orthodontist Madinat Sultan Qaboos | E40: Commercial | F40: 30-80 | G40: Low | H40: Loc+Cat | I40: Dental | J40: /en/orthodontist/madinat-sultan-qaboos | K40: =ROUND((IF(E40="Transactional",5,IF(E40="Commercial",4,IF(E40="Comparison",3,IF(E40="Informational",2,3))))*LOG10(IF(ISNUMBER(L40),L40,IFERROR(VALUE(LEFT(F40,FIND("-",F40)-1)),100))+1))/IF(IF(ISBLANK(M40),G40,M40)="High",5,IF(IF(ISBLANK(M40),G40,M40)="Medium",3,1)),2) -> 5.97 | O40: Not Started | P40: long-tail با رقابت پایین
...

Sheet ۰۶_Tier3_Costs
A1: # | B1: Tier | C1: Lang | D1: Keyword | E1: Intent | F1: Est. Volume | G1: Est. Comp. | H1: Pattern | I1: Cluster | J1: Target URL | K1: Priority | L1: Actual Vol. | M1: Actual Diff. | N1: Current Rank | O1: Status | P1: Notes
A2: 381 | B2: 3 | C2: EN | D2: dental implant cost Muscat | E2: Commercial | F2: 300-700 | G2: Low | H2: Cost | I2: Dental | J2: /en/articles/dental-implant-cost-muscat | K2: =ROUND((IF(E2="Transactional",5,IF(E2="Commercial",4,IF(E2="Comparison",3,IF(E2="Informational",2,3))))*LOG10(IF(ISNUMBER(L2),L2,IFERROR(VALUE(LEFT(F2,FIND("-",F2)-1)),100))+1))/IF(IF(ISBLANK(M2),G2,M2)="High",5,IF(IF(ISBLANK(M2),G2,M2)="Medium",3,1)),2) -> 9.91 | O2: Not Started | P2: intent بالا — کاربر آماده خرید
A3: 382 | B3: 3 | C3: AR | D3: تكلفة زرع الأسنان في مسقط | E3: Commercial | F3: 250-600 | G3: Low | H3: Cost | I3: Dental | J3: /ar/articles/dental-implant-cost | K3: =ROUND((IF(E3="Transactional",5,IF(E3="Commercial",4,IF(E3="Comparison",3,IF(E3="Informational",2,3))))*LOG10(IF(ISNUMBER(L3),L3,IFERROR(VALUE(LEFT(F3,FIND("-",F3)-1)),100))+1))/IF(IF(ISBLANK(M3),G3,M3)="High",5,IF(IF(ISBLANK(M3),G3,M3)="Medium",3,1)),2) -> 9.6 | O3: Not Started
A4: 383 | B4: 3 | C4: EN | D4: teeth whitening cost Muscat | E4: Commercial | F4: 200-500 | G4: Low | H4: Cost | I4: Dental | J4: /en/articles/teeth-whitening-cost-muscat | K4: =ROUND((IF(E4="Transactional",5,IF(E4="Commercial",4,IF(E4="Comparison",3,IF(E4="Informational",2,3))))*LOG10(IF(ISNUMBER(L4),L4,IFERROR(VALUE(LEFT(F4,FIND("-",F4)-1)),100))+1))/IF(IF(ISBLANK(M4),G4,M4)="High",5,IF(IF(ISBLANK(M4),G4,M4)="Medium",3,1)),2) -> 9.21 | O4: Not Started | P4: intent بالا — کاربر آماده خرید
A5: 384 | B5: 3 | C5: AR | D5: تكلفة تبييض الأسنان في مسقط | E5: Commercial | F5: 150-400 | G5: Low | H5: Cost | I5: Dental | J5: /ar/articles/teeth-whitening-cost | K5: =ROUND((IF(E5="Transactional",5,IF(E5="Commercial",4,IF(E5="Comparison",3,IF(E5="Informational",2,3))))*LOG10(IF(ISNUMBER(L5),L5,IFERROR(VALUE(LEFT(F5,FIND("-",F5)-1)),100))+1))/IF(IF(ISBLANK(M5),G5,M5)="High",5,IF(IF(ISBLANK(M5),G5,M5)="Medium",3,1)),2) -> 8.72 | O5: Not Started
A6: 385 | B6: 3 | C6: EN | D6: invisalign cost Muscat | E6: Commercial | F6: 200-500 | G6: Low | H6: Cost | I6: Dental | J6: /en/articles/invisalign-cost-muscat | K6: =ROUND((IF(E6="Transactional",5,IF(E6="Commercial",4,IF(E6="Comparison",3,IF(E6="Informational",2,3))))*LOG10(IF(ISNUMBER(L6),L6,IFERROR(VALUE(LEFT(F6,FIND("-",F6)-1)),100))+1))/IF(IF(ISBLANK(M6),G6,M6)="High",5,IF(IF(ISBLANK(M6),G6,M6)="Medium",3,1)),2) -> 9.21 | O6: Not Started | P6: intent بالا — کاربر آماده خرید
A7: 386 | B7: 3 | C7: AR | D7: تكلفة تقويم شفاف في مسقط | E7: Commercial | F7: 150-400 | G7: Low | H7: Cost | I7: Dental | J7: /ar/articles/invisalign-cost | K7: =ROUND((IF(E7="Transactional",5,IF(E7="Commercial",4,IF(E7="Comparison",3,IF(E7="Informational",2,3))))*LOG10(IF(ISNUMBER(L7),L7,IFERROR(VALUE(LEFT(F7,FIND("-",F7)-1)),100))+1))/IF(IF(ISBLANK(M7),G7,M7)="High",5,IF(IF(ISBLANK(M7),G7,M7)="Medium",3,1)),2) -> 8.72 | O7: Not Started
A8: 387 | B8: 3 | C8: EN | D8: veneers cost Muscat | E8: Commercial | F8: 200-500 | G8: Low | H8: Cost | I8: Dental | J8: /en/articles/veneers-cost-muscat | K8: =ROUND((IF(E8="Transactional",5,IF(E8="Commercial",4,IF(E8="Comparison",3,IF(E8="Informational",2,3))))*LOG10(IF(ISNUMBER(L8),L8,IFERROR(VALUE(LEFT(F8,FIND("-",F8)-1)),100))+1))/IF(IF(ISBLANK(M8),G8,M8)="High",5,IF(IF(ISBLANK(M8),G8,M8)="Medium",3,1)),2) -> 9.21 | O8: Not Started | P8: intent بالا — کاربر آماده خرید
A9: 388 | B9: 3 | C9: AR | D9: تكلفة عدسات الأسنان في مسقط | E9: Commercial | F9: 150-400 | G9: Low | H9: Cost | I9: Dental | J9: /ar/articles/veneers-cost | K9: =ROUND((IF(E9="Transactional",5,IF(E9="Commercial",4,IF(E9="Comparison",3,IF(E9="Informational",2,3))))*LOG10(IF(ISNUMBER(L9),L9,IFERROR(VALUE(LEFT(F9,FIND("-",F9)-1)),100))+1))/IF(IF(ISBLANK(M9),G9,M9)="High",5,IF(IF(ISBLANK(M9),G9,M9)="Medium",3,1)),2) -> 8.72 | O9: Not Started
A10: 389 | B10: 3 | C10: EN | D10: root canal cost Muscat | E10: Commercial | F10: 200-500 | G10: Low | H10: Cost | I10: Dental | J10: /en/articles/root-canal-cost-muscat | K10: =ROUND((IF(E10="Transactional",5,IF(E10="Commercial",4,IF(E10="Comparison",3,IF(E10="Informational",2,3))))*LOG10(IF(ISNUMBER(L10),L10,IFERROR(VALUE(LEFT(F10,FIND("-",F10)-1)),100))+1))/IF(IF(ISBLANK(M10),G10,M10)="High",5,IF(IF(ISBLANK(M10),G10,M10)="Medium",3,1)),2) -> 9.21 | O10: Not Started | P10: intent بالا — کاربر آماده خرید
A11: 390 | B11: 3 | C11: AR | D11: تكلفة علاج العصب في مسقط | E11: Commercial | F11: 150-400 | G11: Low | H11: Cost | I11: Dental | J11: /ar/articles/root-canal-cost | K11: =ROUND((IF(E11="Transactional",5,IF(E11="Commercial",4,IF(E11="Comparison",3,IF(E11="Informational",2,3))))*LOG10(IF(ISNUMBER(L11),L11,IFERROR(VALUE(LEFT(F11,FIND("-",F11)-1)),100))+1))/IF(IF(ISBLANK(M11),G11,M11)="High",5,IF(IF(ISBLANK(M11),G11,M11)="Medium",3,1)),2) -> 8.72 | O11: Not Started
A12: 391 | B12: 3 | C12: EN | D12: LASIK cost Muscat | E12: Commercial | F12: 200-500 | G12: Low | H12: Cost | I12: Eye | J12: /en/articles/lasik-cost-muscat | K12: =ROUND((IF(E12="Transactional",5,IF(E12="Commercial",4,IF(E12="Comparison",3,IF(E12="Informational",2,3))))*LOG10(IF(ISNUMBER(L12),L12,IFERROR(VALUE(LEFT(F12,FIND("-",F12)-1)),100))+1))/IF(IF(ISBLANK(M12),G12,M12)="High",5,IF(IF(ISBLANK(M12),G12,M12)="Medium",3,1)),2) -> 9.21 | O12: Not Started | P12: intent بالا — کاربر آماده خرید
A13: 392 | B13: 3 | C13: AR | D13: تكلفة ليزك في مسقط | E13: Commercial | F13: 150-400 | G13: Low | H13: Cost | I13: Eye | J13: /ar/articles/lasik-cost | K13: =ROUND((IF(E13="Transactional",5,IF(E13="Commercial",4,IF(E13="Comparison",3,IF(E13="Informational",2,3))))*LOG10(IF(ISNUMBER(L13),L13,IFERROR(VALUE(LEFT(F13,FIND("-",F13)-1)),100))+1))/IF(IF(ISBLANK(M13),G13,M13)="High",5,IF(IF(ISBLANK(M13),G13,M13)="Medium",3,1)),2) -> 8.72 | O13: Not Started
A14: 393 | B14: 3 | C14: EN | D14: cataract surgery cost Muscat | E14: Commercial | F14: 100-300 | G14: Low | H14: Cost | I14: Eye | J14: /en/articles/cataract-surgery-cost-muscat | K14: =ROUND((IF(E14="Transactional",5,IF(E14="Commercial",4,IF(E14="Comparison",3,IF(E14="Informational",2,3))))*LOG10(IF(ISNUMBER(L14),L14,IFERROR(VALUE(LEFT(F14,FIND("-",F14)-1)),100))+1))/IF(IF(ISBLANK(M14),G14,M14)="High",5,IF(IF(ISBLANK(M14),G14,M14)="Medium",3,1)),2) -> 8.02 | O14: Not Started | P14: intent بالا — کاربر آماده خرید
A15: 394 | B15: 3 | C15: AR | D15: تكلفة جراحة المياه البيضاء في مسقط | E15: Commercial | F15: 80-250 | G15: Low | H15: Cost | I15: Eye | J15: /ar/articles/cataract-surgery-cost | K15: =ROUND((IF(E15="Transactional",5,IF(E15="Commercial",4,IF(E15="Comparison",3,IF(E15="Informational",2,3))))*LOG10(IF(ISNUMBER(L15),L15,IFERROR(VALUE(LEFT(F15,FIND("-",F15)-1)),100))+1))/IF(IF(ISBLANK(M15),G15,M15)="High",5,IF(IF(ISBLANK(M15),G15,M15)="Medium",3,1)),2) -> 7.63 | O15: Not Started
A16: 395 | B16: 3 | C16: EN | D16: laser hair removal cost Muscat | E16: Commercial | F16: 300-700 | G16: Low | H16: Cost | I16: Aesthetic | J16: /en/articles/laser-hair-removal-cost-muscat | K16: =ROUND((IF(E16="Transactional",5,IF(E16="Commercial",4,IF(E16="Comparison",3,IF(E16="Informational",2,3))))*LOG10(IF(ISNUMBER(L16),L16,IFERROR(VALUE(LEFT(F16,FIND("-",F16)-1)),100))+1))/IF(IF(ISBLANK(M16),G16,M16)="High",5,IF(IF(ISBLANK(M16),G16,M16)="Medium",3,1)),2) -> 9.91 | O16: Not Started | P16: intent بالا — کاربر آماده خرید
A17: 396 | B17: 3 | C17: AR | D17: تكلفة ليزر إزالة الشعر في مسقط | E17: Commercial | F17: 250-600 | G17: Low | H17: Cost | I17: Aesthetic | J17: /ar/articles/laser-hair-removal-cost | K17: =ROUND((IF(E17="Transactional",5,IF(E17="Commercial",4,IF(E17="Comparison",3,IF(E17="Informational",2,3))))*LOG10(IF(ISNUMBER(L17),L17,IFERROR(VALUE(LEFT(F17,FIND("-",F17)-1)),100))+1))/IF(IF(ISBLANK(M17),G17,M17)="High",5,IF(IF(ISBLANK(M17),G17,M17)="Medium",3,1)),2) -> 9.6 | O17: Not Started
A18: 397 | B18: 3 | C18: EN | D18: botox cost Muscat | E18: Commercial | F18: 300-700 | G18: Low | H18: Cost | I18: Aesthetic | J18: /en/articles/botox-cost-muscat | K18: =ROUND((IF(E18="Transactional",5,IF(E18="Commercial",4,IF(E18="Comparison",3,IF(E18="Informational",2,3))))*LOG10(IF(ISNUMBER(L18),L18,IFERROR(VALUE(LEFT(F18,FIND("-",F18)-1)),100))+1))/IF(IF(ISBLANK(M18),G18,M18)="High",5,IF(IF(ISBLANK(M18),G18,M18)="Medium",3,1)),2) -> 9.91 | O18: Not Started | P18: intent بالا — کاربر آماده خرید
A19: 398 | B19: 3 | C19: AR | D19: تكلفة بوتوكس في مسقط | E19: Commercial | F19: 250-600 | G19: Low | H19: Cost | I19: Aesthetic | J19: /ar/articles/botox-cost | K19: =ROUND((IF(E19="Transactional",5,IF(E19="Commercial",4,IF(E19="Comparison",3,IF(E19="Informational",2,3))))*LOG10(IF(ISNUMBER(L19),L19,IFERROR(VALUE(LEFT(F19,FIND("-",F19)-1)),100))+1))/IF(IF(ISBLANK(M19),G19,M19)="High",5,IF(IF(ISBLANK(M19),G19,M19)="Medium",3,1)),2) -> 9.6 | O19: Not Started
A20: 399 | B20: 3 | C20: EN | D20: filler cost Muscat | E20: Commercial | F20: 300-700 | G20: Low | H20: Cost | I20: Aesthetic | J20: /en/articles/filler-cost-muscat | K20: =ROUND((IF(E20="Transactional",5,IF(E20="Commercial",4,IF(E20="Comparison",3,IF(E20="Informational",2,3))))*LOG10(IF(ISNUMBER(L20),L20,IFERROR(VALUE(LEFT(F20,FIND("-",F20)-1)),100))+1))/IF(IF(ISBLANK(M20),G20,M20)="High",5,IF(IF(ISBLANK(M20),G20,M20)="Medium",3,1)),2) -> 9.91 | O20: Not Started | P20: intent بالا — کاربر آماده خرید
A21: 400 | B21: 3 | C21: AR | D21: تكلفة فيلر في مسقط | E21: Commercial | F21: 250-600 | G21: Low | H21: Cost | I21: Aesthetic | J21: /ar/articles/filler-cost | K21: =ROUND((IF(E21="Transactional",5,IF(E21="Commercial",4,IF(E21="Comparison",3,IF(E21="Informational",2,3))))*LOG10(IF(ISNUMBER(L21),L21,IFERROR(VALUE(LEFT(F21,FIND("-",F21)-1)),100))+1))/IF(IF(ISBLANK(M21),G21,M21)="High",5,IF(IF(ISBLANK(M21),G21,M21)="Medium",3,1)),2) -> 9.6 | O21: Not Started
